2024-11-26 13:09:38,105 - INFO - Watching for file changes with StatReloader
2024-11-26 13:09:44,433 - ERROR - Invalid HTTP_HOST header: 'localhost:8000'. You may need to add 'localhost' to ALLOWED_HOSTS.
Traceback (most recent call last):
  File "/Users/carlosvillarino/gestion_archivos/env/lib/python3.12/site-packages/django/core/handlers/exception.py", line 55, in inner
    response = get_response(request)
               ^^^^^^^^^^^^^^^^^^^^^
  File "/Users/carlosvillarino/gestion_archivos/env/lib/python3.12/site-packages/django/utils/deprecation.py", line 128, in __call__
    response = self.process_request(request)
               ^^^^^^^^^^^^^^^^^^^^^^^^^^^^^
  File "/Users/carlosvillarino/gestion_archivos/env/lib/python3.12/site-packages/django/middleware/common.py", line 48, in process_request
    host = request.get_host()
           ^^^^^^^^^^^^^^^^^^
  File "/Users/carlosvillarino/gestion_archivos/env/lib/python3.12/site-packages/django/http/request.py", line 151, in get_host
    raise DisallowedHost(msg)
django.core.exceptions.DisallowedHost: Invalid HTTP_HOST header: 'localhost:8000'. You may need to add 'localhost' to ALLOWED_HOSTS.
2024-11-26 13:09:44,468 - WARNING - Bad Request: /
2024-11-26 13:09:44,469 - WARNING - "GET / HTTP/1.1" 400 67646
2024-11-26 13:09:44,752 - ERROR - Invalid HTTP_HOST header: 'localhost:8000'. You may need to add 'localhost' to ALLOWED_HOSTS.
Traceback (most recent call last):
  File "/Users/carlosvillarino/gestion_archivos/env/lib/python3.12/site-packages/django/core/handlers/exception.py", line 55, in inner
    response = get_response(request)
               ^^^^^^^^^^^^^^^^^^^^^
  File "/Users/carlosvillarino/gestion_archivos/env/lib/python3.12/site-packages/django/utils/deprecation.py", line 128, in __call__
    response = self.process_request(request)
               ^^^^^^^^^^^^^^^^^^^^^^^^^^^^^
  File "/Users/carlosvillarino/gestion_archivos/env/lib/python3.12/site-packages/django/middleware/common.py", line 48, in process_request
    host = request.get_host()
           ^^^^^^^^^^^^^^^^^^
  File "/Users/carlosvillarino/gestion_archivos/env/lib/python3.12/site-packages/django/http/request.py", line 151, in get_host
    raise DisallowedHost(msg)
django.core.exceptions.DisallowedHost: Invalid HTTP_HOST header: 'localhost:8000'. You may need to add 'localhost' to ALLOWED_HOSTS.
2024-11-26 13:09:44,769 - WARNING - Bad Request: /favicon.ico
2024-11-26 13:09:44,769 - WARNING - "GET /favicon.ico HTTP/1.1" 400 67471
2024-11-26 13:10:20,711 - INFO - /Users/carlosvillarino/gestion_archivos/gestion_archivos/settings.py changed, reloading.
2024-11-26 13:10:21,096 - INFO - Watching for file changes with StatReloader
2024-11-26 13:10:22,202 - INFO - "GET / HTTP/1.1" 302 0
2024-11-26 13:10:22,210 - INFO - "GET /login/ HTTP/1.1" 200 2700
2024-11-26 13:10:22,350 - INFO - "GET /static/imagenes/logo.png HTTP/1.1" 200 120200
2024-11-26 13:10:22,689 - INFO - "GET /static/imagenes/fondo.jpg HTTP/1.1" 200 593739
2024-11-26 13:10:22,878 - WARNING - Not Found: /favicon.ico
2024-11-26 13:10:22,878 - WARNING - "GET /favicon.ico HTTP/1.1" 404 4988
2024-11-26 13:10:24,784 - INFO - [Login] Inicio de sesi√≥n exitoso - Usuario: carlos1 (villarinocarlos75@gmail.com)
2024-11-26 13:10:24,797 - INFO - "POST /login/ HTTP/1.1" 302 0
2024-11-26 13:10:24,919 - INFO - "GET / HTTP/1.1" 200 19916
2024-11-26 13:10:27,890 - INFO - "GET /subir/ HTTP/1.1" 200 6731
2024-11-26 13:10:33,890 - INFO - "POST /borrar/1jne-IKbJnUabsGmfkYOtnQWDfG5IuJH8/ HTTP/1.1" 302 0
2024-11-26 13:10:34,003 - INFO - "GET / HTTP/1.1" 200 20073
2024-11-26 13:10:43,335 - INFO - "POST /borrar/1QP505x4947zx3AFyzenB50qVzh7VOaP4/ HTTP/1.1" 302 0
2024-11-26 13:10:43,459 - INFO - "GET / HTTP/1.1" 200 20073
2024-11-26 13:10:51,479 - INFO - "POST /borrar/1zmRKQAuOb0Vnq2jjuqzxDGlJyM71p6ZL/ HTTP/1.1" 302 0
2024-11-26 13:10:51,605 - INFO - "GET / HTTP/1.1" 200 20073
2024-11-26 13:11:45,061 - INFO - "GET /subir/ HTTP/1.1" 200 6731
2024-11-26 13:12:03,830 - ERROR - Internal Server Error: /subir/
Traceback (most recent call last):
  File "/Users/carlosvillarino/gestion_archivos/env/lib/python3.12/site-packages/django/core/handlers/exception.py", line 55, in inner
    response = get_response(request)
               ^^^^^^^^^^^^^^^^^^^^^
  File "/Users/carlosvillarino/gestion_archivos/env/lib/python3.12/site-packages/django/core/handlers/base.py", line 197, in _get_response
    response = wrapped_callback(request, *callback_args, **callback_kwargs)
               ^^^^^^^^^^^^^^^^^^^^^^^^^^^^^^^^^^^^^^^^^^^^^^^^^^^^^^^^^^^^
  File "/Users/carlosvillarino/gestion_archivos/archivos/views.py", line 48, in wrapper
    return view_func(request, *args, **kwargs)
           ^^^^^^^^^^^^^^^^^^^^^^^^^^^^^^^^^^^
  File "/Users/carlosvillarino/gestion_archivos/archivos/views.py", line 160, in subir_archivo
    file_id = subir_a_drive(file_path, archivo.name)
              ^^^^^^^^^^^^^^^^^^^^^^^^^^^^^^^^^^^^^^
  File "/Users/carlosvillarino/gestion_archivos/archivos/views.py", line 73, in subir_a_drive
    file = service.files().create(body=file_metadata, media_body=media, fields='id').execute()
           ^^^^^^^^^^^^^^^^^^^^^^^^^^^^^^^^^^^^^^^^^^^^^^^^^^^^^^^^^^^^^^^^^^^^^^^^^^^^^^^^^^^
  File "/Users/carlosvillarino/gestion_archivos/env/lib/python3.12/site-packages/googleapiclient/_helpers.py", line 130, in positional_wrapper
    return wrapped(*args, **kwargs)
           ^^^^^^^^^^^^^^^^^^^^^^^^
  File "/Users/carlosvillarino/gestion_archivos/env/lib/python3.12/site-packages/googleapiclient/http.py", line 902, in execute
    _, body = self.next_chunk(http=http, num_retries=num_retries)
              ^^^^^^^^^^^^^^^^^^^^^^^^^^^^^^^^^^^^^^^^^^^^^^^^^^^
  File "/Users/carlosvillarino/gestion_archivos/env/lib/python3.12/site-packages/googleapiclient/_helpers.py", line 130, in positional_wrapper
    return wrapped(*args, **kwargs)
           ^^^^^^^^^^^^^^^^^^^^^^^^
  File "/Users/carlosvillarino/gestion_archivos/env/lib/python3.12/site-packages/googleapiclient/http.py", line 1007, in next_chunk
    resp, content = _retry_request(
                    ^^^^^^^^^^^^^^^
  File "/Users/carlosvillarino/gestion_archivos/env/lib/python3.12/site-packages/googleapiclient/http.py", line 191, in _retry_request
    resp, content = http.request(uri, method, *args, **kwargs)
                    ^^^^^^^^^^^^^^^^^^^^^^^^^^^^^^^^^^^^^^^^^^
  File "/Users/carlosvillarino/gestion_archivos/env/lib/python3.12/site-packages/google_auth_httplib2.py", line 209, in request
    self.credentials.before_request(self._request, method, uri, request_headers)
  File "/Users/carlosvillarino/gestion_archivos/env/lib/python3.12/site-packages/google/auth/credentials.py", line 239, in before_request
    self._blocking_refresh(request)
  File "/Users/carlosvillarino/gestion_archivos/env/lib/python3.12/site-packages/google/auth/credentials.py", line 202, in _blocking_refresh
    self.refresh(request)
  File "/Users/carlosvillarino/gestion_archivos/env/lib/python3.12/site-packages/google/oauth2/service_account.py", line 448, in refresh
    access_token, expiry, _ = _client.jwt_grant(
                              ^^^^^^^^^^^^^^^^^^
  File "/Users/carlosvillarino/gestion_archivos/env/lib/python3.12/site-packages/google/oauth2/_client.py", line 298, in jwt_grant
    response_data = _token_endpoint_request(
                    ^^^^^^^^^^^^^^^^^^^^^^^^
  File "/Users/carlosvillarino/gestion_archivos/env/lib/python3.12/site-packages/google/oauth2/_client.py", line 269, in _token_endpoint_request
    _handle_error_response(response_data, retryable_error)
  File "/Users/carlosvillarino/gestion_archivos/env/lib/python3.12/site-packages/google/oauth2/_client.py", line 68, in _handle_error_response
    raise exceptions.RefreshError(
google.auth.exceptions.RefreshError: ('invalid_grant: Invalid JWT Signature.', {'error': 'invalid_grant', 'error_description': 'Invalid JWT Signature.'})
2024-11-26 13:12:03,838 - ERROR - "POST /subir/ HTTP/1.1" 500 139375
2024-11-26 13:15:00,944 - INFO - "POST /borrar/1QP505x4947zx3AFyzenB50qVzh7VOaP4/ HTTP/1.1" 302 0
2024-11-26 13:15:01,057 - INFO - "GET / HTTP/1.1" 200 20073
2024-11-26 13:15:05,272 - INFO - "GET /?page=2 HTTP/1.1" 200 14554
2024-11-26 13:15:06,255 - INFO - "GET /subir/ HTTP/1.1" 200 6731
2024-11-26 13:15:32,120 - ERROR - Internal Server Error: /subir/
Traceback (most recent call last):
  File "/Users/carlosvillarino/gestion_archivos/env/lib/python3.12/site-packages/django/core/handlers/exception.py", line 55, in inner
    response = get_response(request)
               ^^^^^^^^^^^^^^^^^^^^^
  File "/Users/carlosvillarino/gestion_archivos/env/lib/python3.12/site-packages/django/core/handlers/base.py", line 197, in _get_response
    response = wrapped_callback(request, *callback_args, **callback_kwargs)
               ^^^^^^^^^^^^^^^^^^^^^^^^^^^^^^^^^^^^^^^^^^^^^^^^^^^^^^^^^^^^
  File "/Users/carlosvillarino/gestion_archivos/archivos/views.py", line 48, in wrapper
    return view_func(request, *args, **kwargs)
           ^^^^^^^^^^^^^^^^^^^^^^^^^^^^^^^^^^^
  File "/Users/carlosvillarino/gestion_archivos/archivos/views.py", line 160, in subir_archivo
    file_id = subir_a_drive(file_path, archivo.name)
              ^^^^^^^^^^^^^^^^^^^^^^^^^^^^^^^^^^^^^^
  File "/Users/carlosvillarino/gestion_archivos/archivos/views.py", line 73, in subir_a_drive
    file = service.files().create(body=file_metadata, media_body=media, fields='id').execute()
           ^^^^^^^^^^^^^^^^^^^^^^^^^^^^^^^^^^^^^^^^^^^^^^^^^^^^^^^^^^^^^^^^^^^^^^^^^^^^^^^^^^^
  File "/Users/carlosvillarino/gestion_archivos/env/lib/python3.12/site-packages/googleapiclient/_helpers.py", line 130, in positional_wrapper
    return wrapped(*args, **kwargs)
           ^^^^^^^^^^^^^^^^^^^^^^^^
  File "/Users/carlosvillarino/gestion_archivos/env/lib/python3.12/site-packages/googleapiclient/http.py", line 902, in execute
    _, body = self.next_chunk(http=http, num_retries=num_retries)
              ^^^^^^^^^^^^^^^^^^^^^^^^^^^^^^^^^^^^^^^^^^^^^^^^^^^
  File "/Users/carlosvillarino/gestion_archivos/env/lib/python3.12/site-packages/googleapiclient/_helpers.py", line 130, in positional_wrapper
    return wrapped(*args, **kwargs)
           ^^^^^^^^^^^^^^^^^^^^^^^^
  File "/Users/carlosvillarino/gestion_archivos/env/lib/python3.12/site-packages/googleapiclient/http.py", line 1007, in next_chunk
    resp, content = _retry_request(
                    ^^^^^^^^^^^^^^^
  File "/Users/carlosvillarino/gestion_archivos/env/lib/python3.12/site-packages/googleapiclient/http.py", line 191, in _retry_request
    resp, content = http.request(uri, method, *args, **kwargs)
                    ^^^^^^^^^^^^^^^^^^^^^^^^^^^^^^^^^^^^^^^^^^
  File "/Users/carlosvillarino/gestion_archivos/env/lib/python3.12/site-packages/google_auth_httplib2.py", line 209, in request
    self.credentials.before_request(self._request, method, uri, request_headers)
  File "/Users/carlosvillarino/gestion_archivos/env/lib/python3.12/site-packages/google/auth/credentials.py", line 239, in before_request
    self._blocking_refresh(request)
  File "/Users/carlosvillarino/gestion_archivos/env/lib/python3.12/site-packages/google/auth/credentials.py", line 202, in _blocking_refresh
    self.refresh(request)
  File "/Users/carlosvillarino/gestion_archivos/env/lib/python3.12/site-packages/google/oauth2/service_account.py", line 448, in refresh
    access_token, expiry, _ = _client.jwt_grant(
                              ^^^^^^^^^^^^^^^^^^
  File "/Users/carlosvillarino/gestion_archivos/env/lib/python3.12/site-packages/google/oauth2/_client.py", line 298, in jwt_grant
    response_data = _token_endpoint_request(
                    ^^^^^^^^^^^^^^^^^^^^^^^^
  File "/Users/carlosvillarino/gestion_archivos/env/lib/python3.12/site-packages/google/oauth2/_client.py", line 269, in _token_endpoint_request
    _handle_error_response(response_data, retryable_error)
  File "/Users/carlosvillarino/gestion_archivos/env/lib/python3.12/site-packages/google/oauth2/_client.py", line 68, in _handle_error_response
    raise exceptions.RefreshError(
google.auth.exceptions.RefreshError: ('invalid_grant: Invalid JWT Signature.', {'error': 'invalid_grant', 'error_description': 'Invalid JWT Signature.'})
2024-11-26 13:15:32,122 - ERROR - "POST /subir/ HTTP/1.1" 500 139320
